Workbook

Sheet Properties
A1: ลำดับ | B1: จังหวัด | C1: ชื่อโครงการ | D1: เลขที่ห้อง | E1: ตรม | F1: ราคา/ตรม | G1: ราคาซื้อ | H1: เจ้าของ | I1: วันที่
A2: 1 | B2: กทม | C2: Silom Terrace | D2: 57/89 | E2: 32 | F2: =G2/E2 -> 78125 | G2: 2500000 | H2: ศิริวรรณ | I2: 26/11/50
A3: 2 | B3: กทม | C3: I-HOUSE RCA | D3: 39/601 | E3: 24.87 | F3: =G3/E3 -> 41093.687 | G3: 1022000 | H3: ศิริวรรณ | I3: 20/09/2547
A4: 3 | B4: กทม | C4: Diamond | D4: 3006 | E4: 34.61 | F4: =G4/E4 -> 84000 | G4: 2907240 | H4: ศิริวรรณ | I4: 26/11/50
A5: 4 | B5: กทม | C5: Diamond | D5: 3012 | E5: 35.32 | F5: 84000 | G5: =E5*F5 -> 2966880 | H5: ศิริวรรณ | I5: 26/11/50
A6: 5 | B6: กทม | C6: Diamond | D6: 3109 | E6: 34.87 | F6: 84500 | G6: =E6*F6 -> 2946515 | H6: ศิริวรรณ | I6: 26/11/50
A7: 6 | B7: กทม | C7: Diamond | D7: 3111 | E7: 34.87 | F7: 84500 | G7: =E7*F7 -> 2946515 | H7: ศิริวรรณ | I7: 26/11/50
A8: 7 | B8: กทม | C8: LPN ราม16 | D8: 55/53 | E8: 28 | F8: =G8/E8 -> 60714.286 | G8: 1700000
A9: 8 | B9: กทม | C9: ภัทร ศรีพัฒน์ | D9: 15/40 | E9: 31 | F9: =G9/E9 -> 17741.935 | G9: 550000 | H9: ไพโรจน์ | I9: 240823
A10: 9 | B10: กทม | C10: ภัทร ศรีพัฒน์ | D10: 15/334 | E10: 31 | F10: =G10/E10 -> 16774.194 | G10: 520000 | H10: ไพโรจน์ | I10: 240823
A11: 10 | B11: กทม | C11: พีคทาวเวอร์ | D11: 17/112 | E11: 58.38 | F11: =G11/E11 -> 25693.731 | G11: 1500000 | H11: ไพโรจน์ | I11: 240823
A12: 11 | B12: กทม | C12: พีคทาวเวอร์ | D12: 17/299 | E12: 55.48 | F12: =G12/E12 -> 27036.77 | G12: 1500000 | H12: ไพโรจน์ | I12: 241008
A13: 12 | B13: กทม | C13: พีคทาวเวอร์ | D13: 17/39 | E13: 60.15 | F13: =G13/E13 -> 34912.718 | G13: 2100000 | H13: ไพโรจน์ | I13: 241008
A14: 13 | B14: พัทยา | C14: The Palm | D14: A 4207 | E14: 82 | F14: 150000 | G14: =E14*F14 -> 12300000 | H14: - | I14: 20668
A15: 14 | B15: พัทยา | C15: The Palm | D15: A 4407 | E15: 82 | F15: 141541.32 | G15: =E15*F15 -> 11606388 | H15: - | I15: 19/01/56
A16: 15 | B16: พัทยา | C16: The Palm | D16: A 1901 | E16: 33 | F16: 80909 | G16: =E16*F16 -> 2669997 | H16: - | I16: 20668
A17: 16 | B17: พัทยา | C17: Cetus | D17: 3004 | E17: 54.5 | G17: =E17*F17 -> 0 | H17: - | I17: 20668
A18: 17 | B18: พัทยา | C18: The Palm | D18: A 3102 | E18: 97.52 | F18: 157812 | G18: =E18*F18 -> 15389826 | H18: ชินวัฒน์ | I18: 241800
A19: 18 | B19: เขาใหญ่ | C19: ทิวเขา | D19: 97 | E19: 50.09 | F19: =G19/E19 -> 66605.111 | G19: 3336250 | H19: SH,N | I19: 28/04/59
A20: 19 | B20: เขาใหญ่ | C20: ทิวเขา | D20: 98 | E20: 28.6 | F20: =G20/E20 -> 63951.049 | G20: 1829000 | H20: SH,N | I20: 28/04/59
A21: 20 | B21: เขาใหญ่ | C21: ทิวเขา | D21: 112 | E21: 50.09 | F21: =G21/E21 -> 67004.392 | G21: 3356250 | H21: SH,N | I21: 28/04/59
A22: 21 | B22: เขาใหญ่ | C22: ทิวเขา | D22: 113 | E22: 28.6 | F22: =G22/E22 -> 64650.35 | G22: 1849000 | H22: SH,N | I22: 28/04/59
A23: 22 | B23: เขาใหญ่ | C23: Romantic | D23: A 302 | E23: 50 | F23: =G23/E23 -> 73000 | G23: 3650000 | H23: ชินวัฒน์ | I23: 241491
A24: 23 | B24: เขาใหญ่ | C24: Romantic | D24: B 501 | E24: 80 | F24: =G24/E24 -> 73000 | G24: 5840000 | H24: ณภัทร์ | I24: 19/04/61
A25: 24 | B25: เขาใหญ่ | C25: Romantic | D25: B 502 | E25: 50 | F25: =G25/E25 -> 73000 | G25: 3650000 | H25: ณภัทร์ | I25: 241491
A26: 25 | B26: เขาใหญ่ | C26: Romantic | D26: B 503 | E26: 50 | F26: =G26/E26 -> 73000 | G26: 3650000 | H26: ชินวัฒน์ | I26: 19/04/61
A27: 26 | B27: เขาใหญ่ | C27: Romantic | D27: B 504 | E27: 80 | F27: =G27/E27 -> 73000 | G27: 5840000 | H27: ชินวัฒน์ | I27: 241491
A28: 27 | B28: เขาใหญ่ | C28: Romantic | D28: B 506 | E28: 50 | F28: =G28/E28 -> 73000 | G28: 3650000 | H28: ณภัทร์ | I28: 19/04/61
A29: 28 | B29: เขาใหญ่ | C29: Romantic | D29: B 507 | E29: 50 | F29: =G29/E29 -> 73000 | G29: 3650000 | H29: ณภัทร์ | I29: 241491
A30: 29 | B30: เขาใหญ่ | C30: Romantic | D30: B 508 | E30: 80 | F30: =G30/E30 -> 73000 | G30: 5840000 | H30: ชินวัฒน์ | I30: 19/04/61
A31: 30 | B31: พัทยา | C31: Andromedra | D31: 26 F5 | E31: 75 | F31: =G31/E31 -> 145228.8 | G31: 10892160
A32: 31 | B32: พัทยา | C32: Andromedra | D32: 27 F5 | E32: 75 | F32: =G32/E32 -> 145737.6 | G32: 10930320 | H32: ชินวัฒน์ | I32: 26/5/2566
A33: 32 | B33: พัทยา | C33: Florida | D33: B 103 | E33: 46 | F33: =G33/E33 -> 129326.09 | G33: 5949000 | H33: ชินวัฒน์ | I33: 25/12/2567
A34: 33 | B34: พัทยา | C34: Florida | D34: B 104 | E34: 46 | F34: =G34/E34 -> 129326.09 | G34: 5949000
A35: 34 | B35: กทม | C35: KNB | D35: 4209 | E35: 26.92 | F35: =G35/E35 -> 148588.41 | G35: 4000000 | H35: ชินวัฒน์ | I35: 27/06/2566
A36: 35 | B36: กทม | C36: IDEO | D36: A1208 | E36: 28.86 | F36: =G36/E36 -> 158568.12 | G36: 4576276 | H36: ณภัทร์ | I36: 30/6/2566
A37: 36 | B37: กทม | C37: IDEO | D37: A1705 | E37: 28.79 | F37: =G37/E37 -> 162111.71 | G37: 4667196 | H37: ณภัทร์ | I37: 30/6/2566
A38: 37 | B38: กทม | C38: IDEO | D38: A1706 | E38: 28.79 | F38: =G38/E38 -> 161922.26 | G38: 4661742 | H38: ชินวัฒน์ | I38: 30/6/2566
A39: 38 | B39: กทม | C39: IDEO | D39: A1708 | E39: 28.86 | F39: =G39/E39 -> 161527.27 | G39: 4661677 | H39: ชินวัฒน์ | I39: 30/6/2566
A40: 39 | B40: กทม | C40: Life | D40: 996/317 | E40: 35 | F40: =G40/E40 -> 143504.83 | G40: 5022669 | H40: ชินวัฒน์ | I40: 30/01/2568
...

Sheet Rent
A1: ลำดับ | B1: จังหวัด | C1: ชื่อโครงการ | D1: เลขที่ห้อง | E1: ตรม | F1: ราคาค่าเช่า
A2: 1 | B2: กทม | C2: Silom Terrace | D2: 57/89 | E2: 32 | F2: 16000
A3: 2 | B3: กทม | C3: I-HOUSE RCA | D3: 39/601 | E3: 24.87 | F3: 8500
A4: 3 | B4: กทม | C4: Diamond | D4: 3006 | E4: 34.61 | F4: 14000
A5: 4 | B5: กทม | C5: Diamond | D5: 3012 | E5: 35.32 | F5: 13000
A6: 5 | B6: กทม | C6: Diamond | D6: 3109 | E6: 34.87 | F6: 12000
A7: 6 | B7: กทม | C7: Diamond | D7: 3111 | E7: 34.87 | F7: 12000
A8: 7 | B8: กทม | C8: LPN ราม16 | D8: 55/53 | E8: 28 | F8: 8500
A9: 8 | B9: กทม | C9: ภัทร ศรีพัฒน์ | D9: 15/40 | E9: 31 | F9: 3500
A10: 9 | B10: กทม | C10: ภัทร ศรีพัฒน์ | D10: 15/334 | E10: 31 | F10: 3500
A11: 10 | B11: กทม | C11: พีคทาวเวอร์ | D11: 17/112 | E11: 58.38
A12: 11 | B12: กทม | C12: พีคทาวเวอร์ | D12: 17/299 | E12: 55.48
A13: 12 | B13: กทม | C13: พีคทาวเวอร์ | D13: 17/39 | E13: 60.15 | F13: Sold
A14: 13 | B14: พัทยา | C14: The Palm | D14: A 4207 | E14: 82 | F14: Sold
A15: 14 | B15: พัทยา | C15: The Palm | D15: A 4407 | E15: 82 | F15: Sold
A16: 15 | B16: พัทยา | C16: The Palm | D16: A 1901 | E16: 33 | F16: Sold
A17: 16 | B17: พัทยา | C17: Cetus | D17: 3004 | E17: 54.5 | F17: Sold
A18: 17 | B18: พัทยา | C18: The Palm | D18: A 3102 | E18: 97.52 | F18: Sold
A19: 18 | B19: เขาใหญ่ | C19: ทิวเขา | D19: 97 | E19: 50.09 | F19: Sold
A20: 19 | B20: เขาใหญ่ | C20: ทิวเขา | D20: 98 | E20: 28.6 | F20: 7000
A21: 20 | B21: เขาใหญ่ | C21: ทิวเขา | D21: 112 | E21: 50.09 | F21: 14000
A22: 21 | B22: เขาใหญ่ | C22: ทิวเขา | D22: 113 | E22: 28.6 | F22: 7000
A23: 30 | B23: พัทยา | C23: Andromedra | D23: 26 F5 | E23: 75 | F23: 50000
A24: 31 | B24: พัทยา | C24: Andromedra | D24: 27 F5 | E24: 75 | F24: 50000
A25: 32 | B25: พัทยา | C25: Florida | D25: B 103 | E25: 46 | F25: 25000
A26: 33 | B26: พัทยา | C26: Florida | D26: B 104 | E26: 46 | F26: 25000
A27: 34 | B27: กทม | C27: KNB | D27: 4209 | E27: 26.92 | F27: 18500
A28: 35 | B28: กทม | C28: IDEO | D28: A1208 | E28: 28.86 | F28: 22000
A29: 36 | B29: กทม | C29: IDEO | D29: A1705 | E29: 28.79 | F29: 22000
A30: 37 | B30: กทม | C30: IDEO | D30: A1706 | E30: 28.79 | F30: 22000
A31: 38 | B31: กทม | C31: IDEO | D31: A1708 | E31: 28.86 | F31: 23000
A32: 39 | B32: กทม | C32: Life | D32: 996/317 | E32: 35 | F32: 25000
A33: 40 | B33: กทม | C33: Life | D33: 996/374 | E33: 35 | F33: 27000
A34: 41 | B34: กทม | C34: Life | D34: 996/500 | E34: 35 | F34: 25000
A35: 42 | B35: กทม | C35: ORIGIN | D35: 2022 | E35: 22 | F35: 16500

Sheet Sheet2
A1: เลขที่ห้อง | B1: ลำดับ | C1: ชื่อโครงการ
A2: 57/89 | B2: 1 | C2: Silom Terrace
A3: 39/601 | B3: 2 | C3: I-HOUSE RCA
A4: 3006 | B4: 3 | C4: Diamond
A5: 3012 | B5: 4 | C5: Diamond
A6: 3109 | B6: 5 | C6: Diamond
A7: 3111 | B7: 6 | C7: Diamond
A8: 55/53 | B8: 7 | C8: LPN ราม16
A9: 15/40 | B9: 8 | C9: ภัทร ศรีพัฒน์
A10: 15/334 | B10: 9 | C10: ภัทร ศรีพัฒน์
A11: 17/112 | B11: 10 | C11: พีคทาวเวอร์
A12: 17/299 | B12: 11 | C12: พีคทาวเวอร์
A13: 17/39 | B13: 12 | C13: พีคทาวเวอร์
A14: A 4207 | B14: 13 | C14: The Palm
A15: A 4407 | B15: 14 | C15: The Palm
A16: A 1901 | B16: 15 | C16: The Palm
A17: 3004 | B17: 16 | C17: Cetus
A18: A 3102 | B18: 17 | C18: The Palm
A19: 97 | B19: 18 | C19: ทิวเขา
A20: 98 | B20: 19 | C20: ทิวเขา
A21: 112 | B21: 20 | C21: ทิวเขา
A22: 113 | B22: 21 | C22: ทิวเขา
A23: A 302 | B23: 22 | C23: Romantic
A24: B 501 | B24: 23 | C24: Romantic
A25: B 502 | B25: 24 | C25: Romantic
A26: B 503 | B26: 25 | C26: Romantic
A27: B 504 | B27: 26 | C27: Romantic
A28: B 506 | B28: 27 | C28: Romantic
A29: B 507 | B29: 28 | C29: Romantic
A30: B 508 | B30: 29 | C30: Romantic
A31: 26 F5 | B31: 30 | C31: Andromedra
A32: 27 F5 | B32: 31 | C32: Andromedra
A33: B 103 | B33: 32 | C33: Florida
A34: B 104 | B34: 33 | C34: Florida
A35: 4209 | B35: 34 | C35: KNB
A36: A1208 | B36: 35 | C36: IDEO
A37: A1705 | B37: 36 | C37: IDEO
A38: A1706 | B38: 37 | C38: IDEO
A39: A1708 | B39: 38 | C39: IDEO
A40: 996/317 | B40: 39 | C40: Life
...

Sheet Tenants
A1: Contract Number | B1: Prop Number | C1: property | D1: unit_number | E1: tenant_name | F1: Account No。 | G1: contract_start | H1: contract_end | I1: Rent fee | J1: Status
A2: 1 | B2: =VLOOKUP(D2,Sheet2!$A$2:$C$44,2, FALSE) -> 36 | C2: Ideo | D2: A1705 | E2: Narong | F2: xxx-xxx-x056 | G2: 2025-02-15 | H2: 2026-02-14 | I2: 22000 | J2: Done
A3: 2 | B3: =VLOOKUP(D3,Sheet2!$A$2:$C$44,2, FALSE) -> 38 | C3: Ideo | D3: A1708 | E3: Montha / Peem | F3: xxx-xxx-x056 | G3: 2025-02-26 | H3: 2026-02-25 | I3: 23000 | J3: On-going
A4: 3 | B4: =VLOOKUP(D4,Sheet2!$A$2:$C$44,2, FALSE) -> 6 | C4: Diamond | D4: 3111 | E4: Diamond D | F4: xxx-xxx-x426 | G4: 45739 | H4: 46103 | I4: 12000 | J4: Done
A5: 4 | B5: =VLOOKUP(D5,Sheet2!$A$2:$C$44,2, FALSE) -> 40 | C5: Life | D5: 996/374 | E5: Donald | F5: xxx-xxx-x426 | G5: 2025-05-01 | H5: 2026-04-30 | I5: 27000 | J5: On-going
A6: 5 | B6: =VLOOKUP(D6,Sheet2!$A$2:$C$44,2, FALSE) -> 19 | C6: ทิวเขา | D6: 98 | E6: T 1 | F6: xxx-xxx-x426 | G6: 45778 | H6: 46142 | I6: 7000 | J6: On-going
A7: 6 | B7: =VLOOKUP(D7,Sheet2!$A$2:$C$44,2, FALSE) -> 41 | C7: Life | D7: 996/500 | E7: Pimchanok | F7: xxx-xxx-x056 | G7: 2025-05-05 | H7: 2026-05-04 | I7: 25000 | J7: On-going
A8: 7 | B8: =VLOOKUP(D8,Sheet2!$A$2:$C$44,2, FALSE) -> 34 | C8: KNB | D8: 4209 | E8: Torfun | F8: xxx-xxx-x056 | G8: 2025-05-21 | H8: 2026-05-20 | I8: 18500 | J8: On-going
A9: 8 | B9: =VLOOKUP(D9,Sheet2!$A$2:$C$44,2, FALSE) -> 37 | C9: Ideo | D9: A1706 | E9: Sumatra / Nithit | F9: xxx-xxx-x056 | G9: 2025-06-01 | H9: 2026-05-31 | I9: 22000 | J9: On-going
A10: 9 | B10: =VLOOKUP(D10,Sheet2!$A$2:$C$44,2, FALSE) -> 8 | C10: ภัทรศรี | D10: 15/40 | E10: Pat A | F10: xxx-xxx-x426 | G10: 45809 | H10: 46173 | I10: 3500 | J10: On-going
A11: 10 | B11: =VLOOKUP(D11,Sheet2!$A$2:$C$44,2, FALSE) -> 35 | C11: Ideo | D11: A1208 | E11: พูนลาภ | F11: xxx-xxx-x426 | G11: 2025-06-30 | H11: 2026-06-29 | I11: 22000 | J11: On-going
A12: 11 | B12: =VLOOKUP(D12,Sheet2!$A$2:$C$44,2, FALSE) -> 4 | C12: Diamond | D12: 3012 | E12: Diamond B | F12: xxx-xxx-x426 | G12: 45839 | H12: 46203 | I12: 14000 | J12: On-going
A13: 12 | B13: =VLOOKUP(D13,Sheet2!$A$2:$C$44,2, FALSE) -> 21 | C13: ทิวเขา | D13: 113 | E13: T 3 | F13: xxx-xxx-x426 | G13: 45839 | H13: 46203 | I13: 7000 | J13: On-going
A14: 13 | B14: =VLOOKUP(D14,Sheet2!$A$2:$C$44,2, FALSE) -> 42 | C14: Origin | D14: 2022 | E14: Emma | F14: xxx-xxx-x056 | G14: 2025-08-07 | H14: 2026-08-06 | I14: 16500 | J14: On-going
A15: 14 | B15: =VLOOKUP(D15,Sheet2!$A$2:$C$44,2, FALSE) -> 3 | C15: Diamond | D15: 3006 | E15: Diamond A | F15: xxx-xxx-x426 | G15: 45878 | H15: 46242 | I15: 14000 | J15: Cancel
A16: 15 | B16: =VLOOKUP(D16,Sheet2!$A$2:$C$44,2, FALSE) -> 2 | C16: i-house | D16: 39/601 | E16: Somebody | F16: xxx-xxx-x426 | G16: 45895 | H16: 46259 | I16: 6500 | J16: On-going
A17: 16 | B17: =VLOOKUP(D17,Sheet2!$A$2:$C$44,2, FALSE) -> 39 | C17: Life | D17: 996/317 | E17: ภรณ์ชนก | F17: xxx-xxx-x056 | G17: 2025-09-13 | H17: 2026-09-12 | I17: 25000 | J17: On-going
A18: 17 | B18: =VLOOKUP(D18,Sheet2!$A$2:$C$44,2, FALSE) -> 1 | C18: Silom Terrace | D18: 57/89 | E18: Chayapa | F18: xxx-xxx-x056 | G18: 45931 | H18: 46112 | I18: 15000 | J18: Done
A19: 18 | B19: =VLOOKUP(D19,Sheet2!$A$2:$C$44,2, FALSE) -> 7 | C19: Lumphini Ville | D19: 55/53 | E19: Praparat | F19: xxx-xxx-x426 | G19: 45931 | H19: 46295 | I19: 8500 | J19: On-going
A20: 19 | B20: =VLOOKUP(D20,Sheet2!$A$2:$C$44,2, FALSE) -> 31 | C20: Ando | D20: 27 F5 | E20: Richard | F20: xxx-xxx-x056 | G20: 2025-10-07 | H20: 2026-10-06 | I20: 50000 | J20: On-going
A21: 20 | B21: =VLOOKUP(D21,Sheet2!$A$2:$C$44,2, FALSE) -> 5 | C21: Diamond | D21: 3109 | E21: Diamond C | F21: xxx-xxx-x426 | G21: 45962 | H21: 46326 | I21: 12000 | J21: On-going
A22: 21 | B22: =VLOOKUP(D22,Sheet2!$A$2:$C$44,2, FALSE) -> 20 | C22: ทิวเขา | D22: 112 | E22: T 2 | F22: xxx-xxx-x426 | G22: 46033 | H22: 46086 | I22: 14000 | J22: On-going
A23: 22 | B23: =VLOOKUP(D23,Sheet2!$A$2:$C$44,2, FALSE) -> 36 | C23: Ideo | D23: A1705 | E23: Narong | F23: xxx-xxx-x056 | G23: 46078 | H23: 46443 | I23: 22000 | J23: On-going
A24: 23 | B24: =VLOOKUP(D24,Sheet2!$A$2:$C$44,2, FALSE) -> 1 | C24: Silom Terrace | D24: 57/89 | E24: Chayapa | F24: xxx-xxx-x056 | G24: 46113 | H24: 46173 | I24: 15000 | J24: On-going

Sheet Payments
A1: property | B1: unit_number | C1: tenant_name | D1: month | E1: amount_due | F1: amount_paid | G1: payment_date | H1: status
A2: Life | B2: 317 | C2: ภรณ์ชนก | D2: 2025-11 | E2: 25000 | F2: 25000 | G2: 2025-11-12 | H2: paid
A3: Life | B3: 374 | C3: Donald | D3: 2025-11 | E3: 27000 | F3: 0 | H3: late
A4: Life | B4: 500 | C4: Pimchanok | D4: 2025-11 | E4: 25000 | F4: 25000 | G4: 2025-11-06 | H4: paid
A5: Ideo | B5: 1208 | C5: พูนลาภ | D5: 2025-11 | E5: 22000 | F5: 0 | H5: late
A6: Ideo | B6: 1705 | C6: Narong | D6: 2025-11 | E6: 22000 | F6: 22000 | G6: 2025-11-16 | H6: paid
A7: Ideo | B7: 1706 | C7: Sumatra / Nithit | D7: 2025-11 | E7: 22000 | F7: 22000 | G7: 2025-11-01 | H7: paid
A8: Ideo | B8: 1708 | C8: Montha / Peem | D8: 2025-11 | E8: 23000 | F8: 23000 | G8: 2025-11-15 | H8: paid
A9: Origin | B9: 2022 | C9: Emma | D9: 2025-11 | E9: 16500 | F9: 16500 | G9: 2025-11-08 | H9: paid
A10: KNB | B10: 4209 | C10: Torfun | D10: 2025-11 | E10: 18500 | F10: 18500 | G10: 2025-11-24 | H10: paid
A11: Ando | B11: 27F5 | C11: Richard | D11: 2025-11 | E11: 50000 | F11: 50000 | G11: 2025-11-07 | H11: paid
A12: Life | B12: 317 | C12: ภรณ์ชนก | D12: 2025-12 | E12: 25000 | F12: 25000 | G12: 2025-12-14 | H12: paid
A13: Life | B13: 374 | C13: Donald | D13: 2025-12 | E13: 27000 | F13: 0 | H13: late
A14: Life | B14: 500 | C14: Pimchanok | D14: 2025-12 | E14: 25000 | F14: 25000 | G14: 2025-12-06 | H14: paid
A15: Ideo | B15: 1208 | C15: พูนลาภ | D15: 2025-12 | E15: 22000 | F15: 0 | H15: late
A16: Ideo | B16: 1705 | C16: Narong | D16: 2025-12 | E16: 22000 | F16: 22000 | G16: 2026-01-10 | H16: paid
A17: Ideo | B17: 1706 | C17: Sumatra / Nithit | D17: 2025-12 | E17: 22000 | F17: 22000 | G17: 2025-12-02 | H17: paid
A18: Ideo | B18: 1708 | C18: Montha / Peem | D18: 2025-12 | E18: 23000 | F18: 23000 | G18: 2025-12-20 | H18: paid
A19: Origin | B19: 2022 | C19: Emma | D19: 2025-12 | E19: 16500 | F19: 16500 | G19: 2025-12-08 | H19: paid
A20: KNB | B20: 4209 | C20: Torfun | D20: 2025-12 | E20: 18500 | F20: 18500 | G20: 2025-12-23 | H20: paid
A21: Ando | B21: 27F5 | C21: Richard | D21: 2025-12 | E21: 50000 | F21: 50000 | G21: 2025-12-07 | H21: paid
A22: Life | B22: 317 | C22: ภรณ์ชนก | D22: 2026-01 | E22: 25000 | F22: 25000 | G22: 2026-01-14 | H22: paid
A23: Life | B23: 374 | C23: Donald | D23: 2026-01 | E23: 27000 | F23: 27000 | G23: 46023 | H23: Paid
A24: Life | B24: 500 | C24: Pimchanok | D24: 2026-01 | E24: 25000 | F24: 25000 | G24: 2026-01-06 | H24: paid
A25: Ideo | B25: 1208 | C25: พูนลาภ | D25: 2026-01 | E25: 22000 | F25: 22000 | G25: 46026 | H25: Paid
A26: Ideo | B26: 1705 | C26: Narong | D26: 2026-01 | E26: 22000 | F26: 22000 | G26: 2026-01-10 | H26: paid
A27: Ideo | B27: 1706 | C27: Sumatra / Nithit | D27: 2026-01 | E27: 22000 | F27: 22000 | G27: 2026-01-01 | H27: paid
A28: Ideo | B28: 1708 | C28: Montha / Peem | D28: 2026-01 | E28: 23000 | F28: 23000 | G28: 2026-01-26 | H28: paid
A29: Origin | B29: 2022 | C29: Emma | D29: 2026-01 | E29: 16500 | F29: 16500 | G29: 2026-01-08 | H29: paid
A30: KNB | B30: 4209 | C30: Torfun | D30: 2026-01 | E30: 18500 | F30: 18500 | G30: 2026-01-23 | H30: paid
A31: Ando | B31: 27F5 | C31: Richard | D31: 2026-01 | E31: 50000 | F31: 49000 | G31: 2026-01-08 | H31: Paid
A32: I-house | B32: 39/601 | C32: =Tenants!E16 -> Somebody | D32: 2026-01 | E32: 6500 | F32: 6500 | G32: 46016 | H32: Paid
A33: Lumphini | B33: 55/53 | C33: L 1 | D33: 2026-01 | E33: 8500 | F33: 8500 | G33: 46025 | H33: Paid
A34: Diamond | B34: 3006 | C34: D1 | D34: 2026-01 | E34: 14000 | F34: 14000 | G34: 46028 | H34: Paid
A35: Diamond | B35: 3012 | C35: D2 | D35: 2026-01 | E35: 13000 | F35: 13000 | G35: 46031 | H35: Paid
A36: Diamond | B36: 3109 | C36: D3 | D36: 2026-01 | E36: 12000 | F36: 12000 | G36: 46027 | H36: Paid
A37: Diamond | B37: 3111 | C37: D4 | D37: 2026-01 | E37: 13000 | F37: 13000 | G37: 46025 | H37: Paid
A38: ทิวเขา | B38: 98 | C38: T1 | D38: 2026-01 | E38: 7000 | F38: 7000 | G38: 46025 | H38: Paid
A39: ทิวเขา | B39: 112 | C39: T2 | D39: 2026-01 | E39: 42000 | F39: 42000 | G39: 46035 | H39: Paid
A40: ทิวเขา | B40: 113 | C40: T3 | D40: 2026-01 | E40: 7000 | F40: 7000 | G40: 46023 | H40: Paid
...
